2025-10-15 18:54:11.201 | DEBUG    | __main__:main:39 - Начало запуска бота
2025-10-15 18:54:11.202 | INFO     | __main__:main:64 - Команда CommandHandler[callback=CommandsMyBot.start] - успешно добавлена!

2025-10-15 18:54:11.202 | INFO     | __main__:main:64 - Команда CommandHandler[callback=CommandsMyBot.help] - успешно добавлена!

2025-10-15 18:54:11.202 | INFO     | __main__:main:64 - Команда CommandHandler[callback=CommandsMyBot.greeting] - успешно добавлена!

2025-10-15 18:54:11.202 | INFO     | __main__:main:64 - Команда CommandHandler[callback=CommandsMyBot.info] - успешно добавлена!

2025-10-15 18:54:11.202 | INFO     | __main__:main:64 - Команда CommandHandler[callback=CommandsMyBot.day_time] - успешно добавлена!

2025-10-15 18:54:11.202 | INFO     | __main__:main:64 - Команда CommandHandler[callback=CommandsMyBot.author] - успешно добавлена!

2025-10-15 18:54:11.202 | INFO     | __main__:main:64 - Команда CommandHandler[callback=PcCommandsBot.system_info] - успешно добавлена!

2025-10-15 18:54:11.202 | INFO     | __main__:main:64 - Команда CommandHandler[callback=PcCommandsBot.processor_info] - успешно добавлена!

2025-10-15 18:54:11.202 | INFO     | __main__:main:64 - Команда CommandHandler[callback=PcCommandsBot.disk] - успешно добавлена!

2025-10-15 18:54:11.202 | INFO     | __main__:main:64 - Команда CommandHandler[callback=PcCommandsBot.users_system] - успешно добавлена!

2025-10-15 18:54:11.202 | INFO     | __main__:main:64 - Команда CommandHandler[callback=PcCommandsBot.access_memory] - успешно добавлена!

2025-10-15 18:54:11.202 | INFO     | __main__:main:64 - Команда CommandHandler[callback=PcCommandsBot.time_start_system] - успешно добавлена!

2025-10-15 18:54:11.202 | DEBUG    | __main__:main:68 - Добавлен обраточик неизвестных команд
2025-10-15 18:54:11.202 | DEBUG    | __main__:main:71 - Бот запустился

2025-10-15 18:54:11.202 | INFO     | __main__:main:72 - Бот успешно запустился
No error handlers are registered, logging exception.
Traceback (most recent call last):
  File "/home/shurik/tg_bot/venv/lib/python3.12/site-packages/telegram/ext/_utils/networkloop.py", line 134, in network_retry_loop
    await do_action()
  File "/home/shurik/tg_bot/venv/lib/python3.12/site-packages/telegram/ext/_utils/networkloop.py", line 127, in do_action
    action_cb_task.result()
  File "/home/shurik/tg_bot/venv/lib/python3.12/site-packages/telegram/ext/_updater.py", line 340, in polling_action_cb
    updates = await self.bot.get_updates(
              ^^^^^^^^^^^^^^^^^^^^^^^^^^^
  File "/home/shurik/tg_bot/venv/lib/python3.12/site-packages/telegram/ext/_extbot.py", line 676, in get_updates
    updates = await super().get_updates(
              ^^^^^^^^^^^^^^^^^^^^^^^^^^
  File "/home/shurik/tg_bot/venv/lib/python3.12/site-packages/telegram/_bot.py", line 4780, in get_updates
    await self._post(
  File "/home/shurik/tg_bot/venv/lib/python3.12/site-packages/telegram/_bot.py", line 703, in _post
    return await self._do_post(
           ^^^^^^^^^^^^^^^^^^^^
  File "/home/shurik/tg_bot/venv/lib/python3.12/site-packages/telegram/ext/_extbot.py", line 372, in _do_post
    return await super()._do_post(
           ^^^^^^^^^^^^^^^^^^^^^^^
  File "/home/shurik/tg_bot/venv/lib/python3.12/site-packages/telegram/_bot.py", line 732, in _do_post
    result = await request.post(
             ^^^^^^^^^^^^^^^^^^^
  File "/home/shurik/tg_bot/venv/lib/python3.12/site-packages/telegram/request/_baserequest.py", line 198, in post
    result = await self._request_wrapper(
             ^^^^^^^^^^^^^^^^^^^^^^^^^^^^
  File "/home/shurik/tg_bot/venv/lib/python3.12/site-packages/telegram/request/_baserequest.py", line 375, in _request_wrapper
    raise exception
telegram.error.Conflict: Conflict: terminated by other getUpdates request; make sure that only one bot instance is running
No error handlers are registered, logging exception.
Traceback (most recent call last):
  File "/home/shurik/tg_bot/venv/lib/python3.12/site-packages/telegram/ext/_utils/networkloop.py", line 134, in network_retry_loop
    await do_action()
  File "/home/shurik/tg_bot/venv/lib/python3.12/site-packages/telegram/ext/_utils/networkloop.py", line 127, in do_action
    action_cb_task.result()
  File "/home/shurik/tg_bot/venv/lib/python3.12/site-packages/telegram/ext/_updater.py", line 340, in polling_action_cb
    updates = await self.bot.get_updates(
              ^^^^^^^^^^^^^^^^^^^^^^^^^^^
  File "/home/shurik/tg_bot/venv/lib/python3.12/site-packages/telegram/ext/_extbot.py", line 676, in get_updates
    updates = await super().get_updates(
              ^^^^^^^^^^^^^^^^^^^^^^^^^^
  File "/home/shurik/tg_bot/venv/lib/python3.12/site-packages/telegram/_bot.py", line 4780, in get_updates
    await self._post(
  File "/home/shurik/tg_bot/venv/lib/python3.12/site-packages/telegram/_bot.py", line 703, in _post
    return await self._do_post(
           ^^^^^^^^^^^^^^^^^^^^
  File "/home/shurik/tg_bot/venv/lib/python3.12/site-packages/telegram/ext/_extbot.py", line 372, in _do_post
    return await super()._do_post(
           ^^^^^^^^^^^^^^^^^^^^^^^
  File "/home/shurik/tg_bot/venv/lib/python3.12/site-packages/telegram/_bot.py", line 732, in _do_post
    result = await request.post(
             ^^^^^^^^^^^^^^^^^^^
  File "/home/shurik/tg_bot/venv/lib/python3.12/site-packages/telegram/request/_baserequest.py", line 198, in post
    result = await self._request_wrapper(
             ^^^^^^^^^^^^^^^^^^^^^^^^^^^^
  File "/home/shurik/tg_bot/venv/lib/python3.12/site-packages/telegram/request/_baserequest.py", line 375, in _request_wrapper
    raise exception
telegram.error.Conflict: Conflict: terminated by other getUpdates request; make sure that only one bot instance is running
No error handlers are registered, logging exception.
Traceback (most recent call last):
  File "/home/shurik/tg_bot/venv/lib/python3.12/site-packages/telegram/ext/_utils/networkloop.py", line 134, in network_retry_loop
    await do_action()
  File "/home/shurik/tg_bot/venv/lib/python3.12/site-packages/telegram/ext/_utils/networkloop.py", line 127, in do_action
    action_cb_task.result()
  File "/home/shurik/tg_bot/venv/lib/python3.12/site-packages/telegram/ext/_updater.py", line 340, in polling_action_cb
    updates = await self.bot.get_updates(
              ^^^^^^^^^^^^^^^^^^^^^^^^^^^
  File "/home/shurik/tg_bot/venv/lib/python3.12/site-packages/telegram/ext/_extbot.py", line 676, in get_updates
    updates = await super().get_updates(
              ^^^^^^^^^^^^^^^^^^^^^^^^^^
  File "/home/shurik/tg_bot/venv/lib/python3.12/site-packages/telegram/_bot.py", line 4780, in get_updates
    await self._post(
  File "/home/shurik/tg_bot/venv/lib/python3.12/site-packages/telegram/_bot.py", line 703, in _post
    return await self._do_post(
           ^^^^^^^^^^^^^^^^^^^^
  File "/home/shurik/tg_bot/venv/lib/python3.12/site-packages/telegram/ext/_extbot.py", line 372, in _do_post
    return await super()._do_post(
           ^^^^^^^^^^^^^^^^^^^^^^^
  File "/home/shurik/tg_bot/venv/lib/python3.12/site-packages/telegram/_bot.py", line 732, in _do_post
    result = await request.post(
             ^^^^^^^^^^^^^^^^^^^
  File "/home/shurik/tg_bot/venv/lib/python3.12/site-packages/telegram/request/_baserequest.py", line 198, in post
    result = await self._request_wrapper(
             ^^^^^^^^^^^^^^^^^^^^^^^^^^^^
  File "/home/shurik/tg_bot/venv/lib/python3.12/site-packages/telegram/request/_baserequest.py", line 375, in _request_wrapper
    raise exception
telegram.error.Conflict: Conflict: terminated by other getUpdates request; make sure that only one bot instance is running
No error handlers are registered, logging exception.
Traceback (most recent call last):
  File "/home/shurik/tg_bot/venv/lib/python3.12/site-packages/telegram/ext/_utils/networkloop.py", line 134, in network_retry_loop
    await do_action()
  File "/home/shurik/tg_bot/venv/lib/python3.12/site-packages/telegram/ext/_utils/networkloop.py", line 127, in do_action
    action_cb_task.result()
  File "/home/shurik/tg_bot/venv/lib/python3.12/site-packages/telegram/ext/_updater.py", line 340, in polling_action_cb
    updates = await self.bot.get_updates(
              ^^^^^^^^^^^^^^^^^^^^^^^^^^^
  File "/home/shurik/tg_bot/venv/lib/python3.12/site-packages/telegram/ext/_extbot.py", line 676, in get_updates
    updates = await super().get_updates(
              ^^^^^^^^^^^^^^^^^^^^^^^^^^
  File "/home/shurik/tg_bot/venv/lib/python3.12/site-packages/telegram/_bot.py", line 4780, in get_updates
    await self._post(
  File "/home/shurik/tg_bot/venv/lib/python3.12/site-packages/telegram/_bot.py", line 703, in _post
    return await self._do_post(
           ^^^^^^^^^^^^^^^^^^^^
  File "/home/shurik/tg_bot/venv/lib/python3.12/site-packages/telegram/ext/_extbot.py", line 372, in _do_post
    return await super()._do_post(
           ^^^^^^^^^^^^^^^^^^^^^^^
  File "/home/shurik/tg_bot/venv/lib/python3.12/site-packages/telegram/_bot.py", line 732, in _do_post
    result = await request.post(
             ^^^^^^^^^^^^^^^^^^^
  File "/home/shurik/tg_bot/venv/lib/python3.12/site-packages/telegram/request/_baserequest.py", line 198, in post
    result = await self._request_wrapper(
             ^^^^^^^^^^^^^^^^^^^^^^^^^^^^
  File "/home/shurik/tg_bot/venv/lib/python3.12/site-packages/telegram/request/_baserequest.py", line 375, in _request_wrapper
    raise exception
telegram.error.Conflict: Conflict: terminated by other getUpdates request; make sure that only one bot instance is running
No error handlers are registered, logging exception.
Traceback (most recent call last):
  File "/home/shurik/tg_bot/venv/lib/python3.12/site-packages/telegram/ext/_utils/networkloop.py", line 134, in network_retry_loop
    await do_action()
  File "/home/shurik/tg_bot/venv/lib/python3.12/site-packages/telegram/ext/_utils/networkloop.py", line 127, in do_action
    action_cb_task.result()
  File "/home/shurik/tg_bot/venv/lib/python3.12/site-packages/telegram/ext/_updater.py", line 340, in polling_action_cb
    updates = await self.bot.get_updates(
              ^^^^^^^^^^^^^^^^^^^^^^^^^^^
  File "/home/shurik/tg_bot/venv/lib/python3.12/site-packages/telegram/ext/_extbot.py", line 676, in get_updates
    updates = await super().get_updates(
              ^^^^^^^^^^^^^^^^^^^^^^^^^^
  File "/home/shurik/tg_bot/venv/lib/python3.12/site-packages/telegram/_bot.py", line 4780, in get_updates
    await self._post(
  File "/home/shurik/tg_bot/venv/lib/python3.12/site-packages/telegram/_bot.py", line 703, in _post
    return await self._do_post(
           ^^^^^^^^^^^^^^^^^^^^
  File "/home/shurik/tg_bot/venv/lib/python3.12/site-packages/telegram/ext/_extbot.py", line 372, in _do_post
    return await super()._do_post(
           ^^^^^^^^^^^^^^^^^^^^^^^
  File "/home/shurik/tg_bot/venv/lib/python3.12/site-packages/telegram/_bot.py", line 732, in _do_post
    result = await request.post(
             ^^^^^^^^^^^^^^^^^^^
  File "/home/shurik/tg_bot/venv/lib/python3.12/site-packages/telegram/request/_baserequest.py", line 198, in post
    result = await self._request_wrapper(
             ^^^^^^^^^^^^^^^^^^^^^^^^^^^^
  File "/home/shurik/tg_bot/venv/lib/python3.12/site-packages/telegram/request/_baserequest.py", line 375, in _request_wrapper
    raise exception
telegram.error.Conflict: Conflict: terminated by other getUpdates request; make sure that only one bot instance is running
No error handlers are registered, logging exception.
Traceback (most recent call last):
  File "/home/shurik/tg_bot/venv/lib/python3.12/site-packages/telegram/ext/_utils/networkloop.py", line 134, in network_retry_loop
    await do_action()
  File "/home/shurik/tg_bot/venv/lib/python3.12/site-packages/telegram/ext/_utils/networkloop.py", line 127, in do_action
    action_cb_task.result()
  File "/home/shurik/tg_bot/venv/lib/python3.12/site-packages/telegram/ext/_updater.py", line 340, in polling_action_cb
    updates = await self.bot.get_updates(
              ^^^^^^^^^^^^^^^^^^^^^^^^^^^
  File "/home/shurik/tg_bot/venv/lib/python3.12/site-packages/telegram/ext/_extbot.py", line 676, in get_updates
    updates = await super().get_updates(
              ^^^^^^^^^^^^^^^^^^^^^^^^^^
  File "/home/shurik/tg_bot/venv/lib/python3.12/site-packages/telegram/_bot.py", line 4780, in get_updates
    await self._post(
  File "/home/shurik/tg_bot/venv/lib/python3.12/site-packages/telegram/_bot.py", line 703, in _post
    return await self._do_post(
           ^^^^^^^^^^^^^^^^^^^^
  File "/home/shurik/tg_bot/venv/lib/python3.12/site-packages/telegram/ext/_extbot.py", line 372, in _do_post
    return await super()._do_post(
           ^^^^^^^^^^^^^^^^^^^^^^^
  File "/home/shurik/tg_bot/venv/lib/python3.12/site-packages/telegram/_bot.py", line 732, in _do_post
    result = await request.post(
             ^^^^^^^^^^^^^^^^^^^
  File "/home/shurik/tg_bot/venv/lib/python3.12/site-packages/telegram/request/_baserequest.py", line 198, in post
    result = await self._request_wrapper(
             ^^^^^^^^^^^^^^^^^^^^^^^^^^^^
  File "/home/shurik/tg_bot/venv/lib/python3.12/site-packages/telegram/request/_baserequest.py", line 375, in _request_wrapper
    raise exception
telegram.error.Conflict: Conflict: terminated by other getUpdates request; make sure that only one bot instance is running
No error handlers are registered, logging exception.
Traceback (most recent call last):
  File "/home/shurik/tg_bot/venv/lib/python3.12/site-packages/telegram/ext/_utils/networkloop.py", line 134, in network_retry_loop
    await do_action()
  File "/home/shurik/tg_bot/venv/lib/python3.12/site-packages/telegram/ext/_utils/networkloop.py", line 127, in do_action
    action_cb_task.result()
  File "/home/shurik/tg_bot/venv/lib/python3.12/site-packages/telegram/ext/_updater.py", line 340, in polling_action_cb
    updates = await self.bot.get_updates(
              ^^^^^^^^^^^^^^^^^^^^^^^^^^^
  File "/home/shurik/tg_bot/venv/lib/python3.12/site-packages/telegram/ext/_extbot.py", line 676, in get_updates
    updates = await super().get_updates(
              ^^^^^^^^^^^^^^^^^^^^^^^^^^
  File "/home/shurik/tg_bot/venv/lib/python3.12/site-packages/telegram/_bot.py", line 4780, in get_updates
    await self._post(
  File "/home/shurik/tg_bot/venv/lib/python3.12/site-packages/telegram/_bot.py", line 703, in _post
    return await self._do_post(
           ^^^^^^^^^^^^^^^^^^^^
  File "/home/shurik/tg_bot/venv/lib/python3.12/site-packages/telegram/ext/_extbot.py", line 372, in _do_post
    return await super()._do_post(
           ^^^^^^^^^^^^^^^^^^^^^^^
  File "/home/shurik/tg_bot/venv/lib/python3.12/site-packages/telegram/_bot.py", line 732, in _do_post
    result = await request.post(
             ^^^^^^^^^^^^^^^^^^^
  File "/home/shurik/tg_bot/venv/lib/python3.12/site-packages/telegram/request/_baserequest.py", line 198, in post
    result = await self._request_wrapper(
             ^^^^^^^^^^^^^^^^^^^^^^^^^^^^
  File "/home/shurik/tg_bot/venv/lib/python3.12/site-packages/telegram/request/_baserequest.py", line 375, in _request_wrapper
    raise exception
telegram.error.Conflict: Conflict: terminated by other getUpdates request; make sure that only one bot instance is running
No error handlers are registered, logging exception.
Traceback (most recent call last):
  File "/home/shurik/tg_bot/venv/lib/python3.12/site-packages/telegram/ext/_utils/networkloop.py", line 134, in network_retry_loop
    await do_action()
  File "/home/shurik/tg_bot/venv/lib/python3.12/site-packages/telegram/ext/_utils/networkloop.py", line 127, in do_action
    action_cb_task.result()
  File "/home/shurik/tg_bot/venv/lib/python3.12/site-packages/telegram/ext/_updater.py", line 340, in polling_action_cb
    updates = await self.bot.get_updates(
              ^^^^^^^^^^^^^^^^^^^^^^^^^^^
  File "/home/shurik/tg_bot/venv/lib/python3.12/site-packages/telegram/ext/_extbot.py", line 676, in get_updates
    updates = await super().get_updates(
              ^^^^^^^^^^^^^^^^^^^^^^^^^^
  File "/home/shurik/tg_bot/venv/lib/python3.12/site-packages/telegram/_bot.py", line 4780, in get_updates
    await self._post(
  File "/home/shurik/tg_bot/venv/lib/python3.12/site-packages/telegram/_bot.py", line 703, in _post
    return await self._do_post(
           ^^^^^^^^^^^^^^^^^^^^
  File "/home/shurik/tg_bot/venv/lib/python3.12/site-packages/telegram/ext/_extbot.py", line 372, in _do_post
    return await super()._do_post(
           ^^^^^^^^^^^^^^^^^^^^^^^
  File "/home/shurik/tg_bot/venv/lib/python3.12/site-packages/telegram/_bot.py", line 732, in _do_post
    result = await request.post(
             ^^^^^^^^^^^^^^^^^^^
  File "/home/shurik/tg_bot/venv/lib/python3.12/site-packages/telegram/request/_baserequest.py", line 198, in post
    result = await self._request_wrapper(
             ^^^^^^^^^^^^^^^^^^^^^^^^^^^^
  File "/home/shurik/tg_bot/venv/lib/python3.12/site-packages/telegram/request/_baserequest.py", line 375, in _request_wrapper
    raise exception
telegram.error.Conflict: Conflict: terminated by other getUpdates request; make sure that only one bot instance is running
No error handlers are registered, logging exception.
Traceback (most recent call last):
  File "/home/shurik/tg_bot/venv/lib/python3.12/site-packages/telegram/ext/_utils/networkloop.py", line 134, in network_retry_loop
    await do_action()
  File "/home/shurik/tg_bot/venv/lib/python3.12/site-packages/telegram/ext/_utils/networkloop.py", line 127, in do_action
    action_cb_task.result()
  File "/home/shurik/tg_bot/venv/lib/python3.12/site-packages/telegram/ext/_updater.py", line 340, in polling_action_cb
    updates = await self.bot.get_updates(
              ^^^^^^^^^^^^^^^^^^^^^^^^^^^
  File "/home/shurik/tg_bot/venv/lib/python3.12/site-packages/telegram/ext/_extbot.py", line 676, in get_updates
    updates = await super().get_updates(
              ^^^^^^^^^^^^^^^^^^^^^^^^^^
  File "/home/shurik/tg_bot/venv/lib/python3.12/site-packages/telegram/_bot.py", line 4780, in get_updates
    await self._post(
  File "/home/shurik/tg_bot/venv/lib/python3.12/site-packages/telegram/_bot.py", line 703, in _post
    return await self._do_post(
           ^^^^^^^^^^^^^^^^^^^^
  File "/home/shurik/tg_bot/venv/lib/python3.12/site-packages/telegram/ext/_extbot.py", line 372, in _do_post
    return await super()._do_post(
           ^^^^^^^^^^^^^^^^^^^^^^^
  File "/home/shurik/tg_bot/venv/lib/python3.12/site-packages/telegram/_bot.py", line 732, in _do_post
    result = await request.post(
             ^^^^^^^^^^^^^^^^^^^
  File "/home/shurik/tg_bot/venv/lib/python3.12/site-packages/telegram/request/_baserequest.py", line 198, in post
    result = await self._request_wrapper(
             ^^^^^^^^^^^^^^^^^^^^^^^^^^^^
  File "/home/shurik/tg_bot/venv/lib/python3.12/site-packages/telegram/request/_baserequest.py", line 375, in _request_wrapper
    raise exception
telegram.error.Conflict: Conflict: terminated by other getUpdates request; make sure that only one bot instance is running
No error handlers are registered, logging exception.
Traceback (most recent call last):
  File "/home/shurik/tg_bot/venv/lib/python3.12/site-packages/telegram/ext/_utils/networkloop.py", line 134, in network_retry_loop
    await do_action()
  File "/home/shurik/tg_bot/venv/lib/python3.12/site-packages/telegram/ext/_utils/networkloop.py", line 127, in do_action
    action_cb_task.result()
  File "/home/shurik/tg_bot/venv/lib/python3.12/site-packages/telegram/ext/_updater.py", line 340, in polling_action_cb
    updates = await self.bot.get_updates(
              ^^^^^^^^^^^^^^^^^^^^^^^^^^^
  File "/home/shurik/tg_bot/venv/lib/python3.12/site-packages/telegram/ext/_extbot.py", line 676, in get_updates
    updates = await super().get_updates(
              ^^^^^^^^^^^^^^^^^^^^^^^^^^
  File "/home/shurik/tg_bot/venv/lib/python3.12/site-packages/telegram/_bot.py", line 4780, in get_updates
    await self._post(
  File "/home/shurik/tg_bot/venv/lib/python3.12/site-packages/telegram/_bot.py", line 703, in _post
    return await self._do_post(
           ^^^^^^^^^^^^^^^^^^^^
  File "/home/shurik/tg_bot/venv/lib/python3.12/site-packages/telegram/ext/_extbot.py", line 372, in _do_post
    return await super()._do_post(
           ^^^^^^^^^^^^^^^^^^^^^^^
  File "/home/shurik/tg_bot/venv/lib/python3.12/site-packages/telegram/_bot.py", line 732, in _do_post
    result = await request.post(
             ^^^^^^^^^^^^^^^^^^^
  File "/home/shurik/tg_bot/venv/lib/python3.12/site-packages/telegram/request/_baserequest.py", line 198, in post
    result = await self._request_wrapper(
             ^^^^^^^^^^^^^^^^^^^^^^^^^^^^
  File "/home/shurik/tg_bot/venv/lib/python3.12/site-packages/telegram/request/_baserequest.py", line 375, in _request_wrapper
    raise exception
telegram.error.Conflict: Conflict: terminated by other getUpdates request; make sure that only one bot instance is running
No error handlers are registered, logging exception.
Traceback (most recent call last):
  File "/home/shurik/tg_bot/venv/lib/python3.12/site-packages/telegram/ext/_utils/networkloop.py", line 134, in network_retry_loop
    await do_action()
  File "/home/shurik/tg_bot/venv/lib/python3.12/site-packages/telegram/ext/_utils/networkloop.py", line 127, in do_action
    action_cb_task.result()
  File "/home/shurik/tg_bot/venv/lib/python3.12/site-packages/telegram/ext/_updater.py", line 340, in polling_action_cb
    updates = await self.bot.get_updates(
              ^^^^^^^^^^^^^^^^^^^^^^^^^^^
  File "/home/shurik/tg_bot/venv/lib/python3.12/site-packages/telegram/ext/_extbot.py", line 676, in get_updates
    updates = await super().get_updates(
              ^^^^^^^^^^^^^^^^^^^^^^^^^^
  File "/home/shurik/tg_bot/venv/lib/python3.12/site-packages/telegram/_bot.py", line 4780, in get_updates
    await self._post(
  File "/home/shurik/tg_bot/venv/lib/python3.12/site-packages/telegram/_bot.py", line 703, in _post
    return await self._do_post(
           ^^^^^^^^^^^^^^^^^^^^
  File "/home/shurik/tg_bot/venv/lib/python3.12/site-packages/telegram/ext/_extbot.py", line 372, in _do_post
    return await super()._do_post(
           ^^^^^^^^^^^^^^^^^^^^^^^
  File "/home/shurik/tg_bot/venv/lib/python3.12/site-packages/telegram/_bot.py", line 732, in _do_post
    result = await request.post(
             ^^^^^^^^^^^^^^^^^^^
  File "/home/shurik/tg_bot/venv/lib/python3.12/site-packages/telegram/request/_baserequest.py", line 198, in post
    result = await self._request_wrapper(
             ^^^^^^^^^^^^^^^^^^^^^^^^^^^^
  File "/home/shurik/tg_bot/venv/lib/python3.12/site-packages/telegram/request/_baserequest.py", line 375, in _request_wrapper
    raise exception
telegram.error.Conflict: Conflict: terminated by other getUpdates request; make sure that only one bot instance is running
No error handlers are registered, logging exception.
Traceback (most recent call last):
  File "/home/shurik/tg_bot/venv/lib/python3.12/site-packages/telegram/ext/_utils/networkloop.py", line 134, in network_retry_loop
    await do_action()
  File "/home/shurik/tg_bot/venv/lib/python3.12/site-packages/telegram/ext/_utils/networkloop.py", line 127, in do_action
    action_cb_task.result()
  File "/home/shurik/tg_bot/venv/lib/python3.12/site-packages/telegram/ext/_updater.py", line 340, in polling_action_cb
    updates = await self.bot.get_updates(
              ^^^^^^^^^^^^^^^^^^^^^^^^^^^
  File "/home/shurik/tg_bot/venv/lib/python3.12/site-packages/telegram/ext/_extbot.py", line 676, in get_updates
    updates = await super().get_updates(
              ^^^^^^^^^^^^^^^^^^^^^^^^^^
  File "/home/shurik/tg_bot/venv/lib/python3.12/site-packages/telegram/_bot.py", line 4780, in get_updates
    await self._post(
  File "/home/shurik/tg_bot/venv/lib/python3.12/site-packages/telegram/_bot.py", line 703, in _post
    return await self._do_post(
           ^^^^^^^^^^^^^^^^^^^^
  File "/home/shurik/tg_bot/venv/lib/python3.12/site-packages/telegram/ext/_extbot.py", line 372, in _do_post
    return await super()._do_post(
           ^^^^^^^^^^^^^^^^^^^^^^^
  File "/home/shurik/tg_bot/venv/lib/python3.12/site-packages/telegram/_bot.py", line 732, in _do_post
    result = await request.post(
             ^^^^^^^^^^^^^^^^^^^
  File "/home/shurik/tg_bot/venv/lib/python3.12/site-packages/telegram/request/_baserequest.py", line 198, in post
    result = await self._request_wrapper(
             ^^^^^^^^^^^^^^^^^^^^^^^^^^^^
  File "/home/shurik/tg_bot/venv/lib/python3.12/site-packages/telegram/request/_baserequest.py", line 375, in _request_wrapper
    raise exception
telegram.error.Conflict: Conflict: terminated by other getUpdates request; make sure that only one bot instance is running
No error handlers are registered, logging exception.
Traceback (most recent call last):
  File "/home/shurik/tg_bot/venv/lib/python3.12/site-packages/telegram/ext/_utils/networkloop.py", line 134, in network_retry_loop
    await do_action()
  File "/home/shurik/tg_bot/venv/lib/python3.12/site-packages/telegram/ext/_utils/networkloop.py", line 127, in do_action
    action_cb_task.result()
  File "/home/shurik/tg_bot/venv/lib/python3.12/site-packages/telegram/ext/_updater.py", line 340, in polling_action_cb
    updates = await self.bot.get_updates(
              ^^^^^^^^^^^^^^^^^^^^^^^^^^^
  File "/home/shurik/tg_bot/venv/lib/python3.12/site-packages/telegram/ext/_extbot.py", line 676, in get_updates
    updates = await super().get_updates(
              ^^^^^^^^^^^^^^^^^^^^^^^^^^
  File "/home/shurik/tg_bot/venv/lib/python3.12/site-packages/telegram/_bot.py", line 4780, in get_updates
    await self._post(
  File "/home/shurik/tg_bot/venv/lib/python3.12/site-packages/telegram/_bot.py", line 703, in _post
    return await self._do_post(
           ^^^^^^^^^^^^^^^^^^^^
  File "/home/shurik/tg_bot/venv/lib/python3.12/site-packages/telegram/ext/_extbot.py", line 372, in _do_post
    return await super()._do_post(
           ^^^^^^^^^^^^^^^^^^^^^^^
  File "/home/shurik/tg_bot/venv/lib/python3.12/site-packages/telegram/_bot.py", line 732, in _do_post
    result = await request.post(
             ^^^^^^^^^^^^^^^^^^^
  File "/home/shurik/tg_bot/venv/lib/python3.12/site-packages/telegram/request/_baserequest.py", line 198, in post
    result = await self._request_wrapper(
             ^^^^^^^^^^^^^^^^^^^^^^^^^^^^
  File "/home/shurik/tg_bot/venv/lib/python3.12/site-packages/telegram/request/_baserequest.py", line 375, in _request_wrapper
    raise exception
telegram.error.Conflict: Conflict: terminated by other getUpdates request; make sure that only one bot instance is running
No error handlers are registered, logging exception.
Traceback (most recent call last):
  File "/home/shurik/tg_bot/venv/lib/python3.12/site-packages/telegram/ext/_utils/networkloop.py", line 134, in network_retry_loop
    await do_action()
  File "/home/shurik/tg_bot/venv/lib/python3.12/site-packages/telegram/ext/_utils/networkloop.py", line 127, in do_action
    action_cb_task.result()
  File "/home/shurik/tg_bot/venv/lib/python3.12/site-packages/telegram/ext/_updater.py", line 340, in polling_action_cb
    updates = await self.bot.get_updates(
              ^^^^^^^^^^^^^^^^^^^^^^^^^^^
  File "/home/shurik/tg_bot/venv/lib/python3.12/site-packages/telegram/ext/_extbot.py", line 676, in get_updates
    updates = await super().get_updates(
              ^^^^^^^^^^^^^^^^^^^^^^^^^^
  File "/home/shurik/tg_bot/venv/lib/python3.12/site-packages/telegram/_bot.py", line 4780, in get_updates
    await self._post(
  File "/home/shurik/tg_bot/venv/lib/python3.12/site-packages/telegram/_bot.py", line 703, in _post
    return await self._do_post(
           ^^^^^^^^^^^^^^^^^^^^
  File "/home/shurik/tg_bot/venv/lib/python3.12/site-packages/telegram/ext/_extbot.py", line 372, in _do_post
    return await super()._do_post(
           ^^^^^^^^^^^^^^^^^^^^^^^
  File "/home/shurik/tg_bot/venv/lib/python3.12/site-packages/telegram/_bot.py", line 732, in _do_post
    result = await request.post(
             ^^^^^^^^^^^^^^^^^^^
  File "/home/shurik/tg_bot/venv/lib/python3.12/site-packages/telegram/request/_baserequest.py", line 198, in post
    result = await self._request_wrapper(
             ^^^^^^^^^^^^^^^^^^^^^^^^^^^^
  File "/home/shurik/tg_bot/venv/lib/python3.12/site-packages/telegram/request/_baserequest.py", line 375, in _request_wrapper
    raise exception
telegram.error.Conflict: Conflict: terminated by other getUpdates request; make sure that only one bot instance is running
No error handlers are registered, logging exception.
Traceback (most recent call last):
  File "/home/shurik/tg_bot/venv/lib/python3.12/site-packages/telegram/ext/_utils/networkloop.py", line 134, in network_retry_loop
    await do_action()
  File "/home/shurik/tg_bot/venv/lib/python3.12/site-packages/telegram/ext/_utils/networkloop.py", line 127, in do_action
    action_cb_task.result()
  File "/home/shurik/tg_bot/venv/lib/python3.12/site-packages/telegram/ext/_updater.py", line 340, in polling_action_cb
    updates = await self.bot.get_updates(
              ^^^^^^^^^^^^^^^^^^^^^^^^^^^
  File "/home/shurik/tg_bot/venv/lib/python3.12/site-packages/telegram/ext/_extbot.py", line 676, in get_updates
    updates = await super().get_updates(
              ^^^^^^^^^^^^^^^^^^^^^^^^^^
  File "/home/shurik/tg_bot/venv/lib/python3.12/site-packages/telegram/_bot.py", line 4780, in get_updates
    await self._post(
  File "/home/shurik/tg_bot/venv/lib/python3.12/site-packages/telegram/_bot.py", line 703, in _post
    return await self._do_post(
           ^^^^^^^^^^^^^^^^^^^^
  File "/home/shurik/tg_bot/venv/lib/python3.12/site-packages/telegram/ext/_extbot.py", line 372, in _do_post
    return await super()._do_post(
           ^^^^^^^^^^^^^^^^^^^^^^^
  File "/home/shurik/tg_bot/venv/lib/python3.12/site-packages/telegram/_bot.py", line 732, in _do_post
    result = await request.post(
             ^^^^^^^^^^^^^^^^^^^
  File "/home/shurik/tg_bot/venv/lib/python3.12/site-packages/telegram/request/_baserequest.py", line 198, in post
    result = await self._request_wrapper(
             ^^^^^^^^^^^^^^^^^^^^^^^^^^^^
  File "/home/shurik/tg_bot/venv/lib/python3.12/site-packages/telegram/request/_baserequest.py", line 375, in _request_wrapper
    raise exception
telegram.error.Conflict: Conflict: terminated by other getUpdates request; make sure that only one bot instance is running
No error handlers are registered, logging exception.
Traceback (most recent call last):
  File "/home/shurik/tg_bot/venv/lib/python3.12/site-packages/telegram/ext/_utils/networkloop.py", line 134, in network_retry_loop
    await do_action()
  File "/home/shurik/tg_bot/venv/lib/python3.12/site-packages/telegram/ext/_utils/networkloop.py", line 127, in do_action
    action_cb_task.result()
  File "/home/shurik/tg_bot/venv/lib/python3.12/site-packages/telegram/ext/_updater.py", line 340, in polling_action_cb
    updates = await self.bot.get_updates(
              ^^^^^^^^^^^^^^^^^^^^^^^^^^^
  File "/home/shurik/tg_bot/venv/lib/python3.12/site-packages/telegram/ext/_extbot.py", line 676, in get_updates
    updates = await super().get_updates(
              ^^^^^^^^^^^^^^^^^^^^^^^^^^
  File "/home/shurik/tg_bot/venv/lib/python3.12/site-packages/telegram/_bot.py", line 4780, in get_updates
    await self._post(
  File "/home/shurik/tg_bot/venv/lib/python3.12/site-packages/telegram/_bot.py", line 703, in _post
    return await self._do_post(
           ^^^^^^^^^^^^^^^^^^^^
  File "/home/shurik/tg_bot/venv/lib/python3.12/site-packages/telegram/ext/_extbot.py", line 372, in _do_post
    return await super()._do_post(
           ^^^^^^^^^^^^^^^^^^^^^^^
  File "/home/shurik/tg_bot/venv/lib/python3.12/site-packages/telegram/_bot.py", line 732, in _do_post
    result = await request.post(
             ^^^^^^^^^^^^^^^^^^^
  File "/home/shurik/tg_bot/venv/lib/python3.12/site-packages/telegram/request/_baserequest.py", line 198, in post
    result = await self._request_wrapper(
             ^^^^^^^^^^^^^^^^^^^^^^^^^^^^
  File "/home/shurik/tg_bot/venv/lib/python3.12/site-packages/telegram/request/_baserequest.py", line 375, in _request_wrapper
    raise exception
telegram.error.Conflict: Conflict: terminated by other getUpdates request; make sure that only one bot instance is running
No error handlers are registered, logging exception.
Traceback (most recent call last):
  File "/home/shurik/tg_bot/venv/lib/python3.12/site-packages/telegram/ext/_utils/networkloop.py", line 134, in network_retry_loop
    await do_action()
  File "/home/shurik/tg_bot/venv/lib/python3.12/site-packages/telegram/ext/_utils/networkloop.py", line 127, in do_action
    action_cb_task.result()
  File "/home/shurik/tg_bot/venv/lib/python3.12/site-packages/telegram/ext/_updater.py", line 340, in polling_action_cb
    updates = await self.bot.get_updates(
              ^^^^^^^^^^^^^^^^^^^^^^^^^^^
  File "/home/shurik/tg_bot/venv/lib/python3.12/site-packages/telegram/ext/_extbot.py", line 676, in get_updates
    updates = await super().get_updates(
              ^^^^^^^^^^^^^^^^^^^^^^^^^^
  File "/home/shurik/tg_bot/venv/lib/python3.12/site-packages/telegram/_bot.py", line 4780, in get_updates
    await self._post(
  File "/home/shurik/tg_bot/venv/lib/python3.12/site-packages/telegram/_bot.py", line 703, in _post
    return await self._do_post(
           ^^^^^^^^^^^^^^^^^^^^
  File "/home/shurik/tg_bot/venv/lib/python3.12/site-packages/telegram/ext/_extbot.py", line 372, in _do_post
    return await super()._do_post(
           ^^^^^^^^^^^^^^^^^^^^^^^
  File "/home/shurik/tg_bot/venv/lib/python3.12/site-packages/telegram/_bot.py", line 732, in _do_post
    result = await request.post(
             ^^^^^^^^^^^^^^^^^^^
  File "/home/shurik/tg_bot/venv/lib/python3.12/site-packages/telegram/request/_baserequest.py", line 198, in post
    result = await self._request_wrapper(
             ^^^^^^^^^^^^^^^^^^^^^^^^^^^^
  File "/home/shurik/tg_bot/venv/lib/python3.12/site-packages/telegram/request/_baserequest.py", line 375, in _request_wrapper
    raise exception
telegram.error.Conflict: Conflict: terminated by other getUpdates request; make sure that only one bot instance is running
No error handlers are registered, logging exception.
Traceback (most recent call last):
  File "/home/shurik/tg_bot/venv/lib/python3.12/site-packages/telegram/ext/_utils/networkloop.py", line 134, in network_retry_loop
    await do_action()
  File "/home/shurik/tg_bot/venv/lib/python3.12/site-packages/telegram/ext/_utils/networkloop.py", line 127, in do_action
    action_cb_task.result()
  File "/home/shurik/tg_bot/venv/lib/python3.12/site-packages/telegram/ext/_updater.py", line 340, in polling_action_cb
    updates = await self.bot.get_updates(
              ^^^^^^^^^^^^^^^^^^^^^^^^^^^
  File "/home/shurik/tg_bot/venv/lib/python3.12/site-packages/telegram/ext/_extbot.py", line 676, in get_updates
    updates = await super().get_updates(
              ^^^^^^^^^^^^^^^^^^^^^^^^^^
  File "/home/shurik/tg_bot/venv/lib/python3.12/site-packages/telegram/_bot.py", line 4780, in get_updates
    await self._post(
  File "/home/shurik/tg_bot/venv/lib/python3.12/site-packages/telegram/_bot.py", line 703, in _post
    return await self._do_post(
           ^^^^^^^^^^^^^^^^^^^^
  File "/home/shurik/tg_bot/venv/lib/python3.12/site-packages/telegram/ext/_extbot.py", line 372, in _do_post
    return await super()._do_post(
           ^^^^^^^^^^^^^^^^^^^^^^^
  File "/home/shurik/tg_bot/venv/lib/python3.12/site-packages/telegram/_bot.py", line 732, in _do_post
    result = await request.post(
             ^^^^^^^^^^^^^^^^^^^
  File "/home/shurik/tg_bot/venv/lib/python3.12/site-packages/telegram/request/_baserequest.py", line 198, in post
    result = await self._request_wrapper(
             ^^^^^^^^^^^^^^^^^^^^^^^^^^^^
  File "/home/shurik/tg_bot/venv/lib/python3.12/site-packages/telegram/request/_baserequest.py", line 375, in _request_wrapper
    raise exception
telegram.error.Conflict: Conflict: terminated by other getUpdates request; make sure that only one bot instance is running
No error handlers are registered, logging exception.
Traceback (most recent call last):
  File "/home/shurik/tg_bot/venv/lib/python3.12/site-packages/telegram/ext/_utils/networkloop.py", line 134, in network_retry_loop
    await do_action()
  File "/home/shurik/tg_bot/venv/lib/python3.12/site-packages/telegram/ext/_utils/networkloop.py", line 127, in do_action
    action_cb_task.result()
  File "/home/shurik/tg_bot/venv/lib/python3.12/site-packages/telegram/ext/_updater.py", line 340, in polling_action_cb
    updates = await self.bot.get_updates(
              ^^^^^^^^^^^^^^^^^^^^^^^^^^^
  File "/home/shurik/tg_bot/venv/lib/python3.12/site-packages/telegram/ext/_extbot.py", line 676, in get_updates
    updates = await super().get_updates(
              ^^^^^^^^^^^^^^^^^^^^^^^^^^
  File "/home/shurik/tg_bot/venv/lib/python3.12/site-packages/telegram/_bot.py", line 4780, in get_updates
    await self._post(
  File "/home/shurik/tg_bot/venv/lib/python3.12/site-packages/telegram/_bot.py", line 703, in _post
    return await self._do_post(
           ^^^^^^^^^^^^^^^^^^^^
  File "/home/shurik/tg_bot/venv/lib/python3.12/site-packages/telegram/ext/_extbot.py", line 372, in _do_post
    return await super()._do_post(
           ^^^^^^^^^^^^^^^^^^^^^^^
  File "/home/shurik/tg_bot/venv/lib/python3.12/site-packages/telegram/_bot.py", line 732, in _do_post
    result = await request.post(
             ^^^^^^^^^^^^^^^^^^^
  File "/home/shurik/tg_bot/venv/lib/python3.12/site-packages/telegram/request/_baserequest.py", line 198, in post
    result = await self._request_wrapper(
             ^^^^^^^^^^^^^^^^^^^^^^^^^^^^
  File "/home/shurik/tg_bot/venv/lib/python3.12/site-packages/telegram/request/_baserequest.py", line 375, in _request_wrapper
    raise exception
telegram.error.Conflict: Conflict: terminated by other getUpdates request; make sure that only one bot instance is running
No error handlers are registered, logging exception.
Traceback (most recent call last):
  File "/home/shurik/tg_bot/venv/lib/python3.12/site-packages/telegram/ext/_utils/networkloop.py", line 134, in network_retry_loop
    await do_action()
  File "/home/shurik/tg_bot/venv/lib/python3.12/site-packages/telegram/ext/_utils/networkloop.py", line 127, in do_action
    action_cb_task.result()
  File "/home/shurik/tg_bot/venv/lib/python3.12/site-packages/telegram/ext/_updater.py", line 340, in polling_action_cb
    updates = await self.bot.get_updates(
              ^^^^^^^^^^^^^^^^^^^^^^^^^^^
  File "/home/shurik/tg_bot/venv/lib/python3.12/site-packages/telegram/ext/_extbot.py", line 676, in get_updates
    updates = await super().get_updates(
              ^^^^^^^^^^^^^^^^^^^^^^^^^^
  File "/home/shurik/tg_bot/venv/lib/python3.12/site-packages/telegram/_bot.py", line 4780, in get_updates
    await self._post(
  File "/home/shurik/tg_bot/venv/lib/python3.12/site-packages/telegram/_bot.py", line 703, in _post
    return await self._do_post(
           ^^^^^^^^^^^^^^^^^^^^
  File "/home/shurik/tg_bot/venv/lib/python3.12/site-packages/telegram/ext/_extbot.py", line 372, in _do_post
    return await super()._do_post(
           ^^^^^^^^^^^^^^^^^^^^^^^
  File "/home/shurik/tg_bot/venv/lib/python3.12/site-packages/telegram/_bot.py", line 732, in _do_post
    result = await request.post(
             ^^^^^^^^^^^^^^^^^^^
  File "/home/shurik/tg_bot/venv/lib/python3.12/site-packages/telegram/request/_baserequest.py", line 198, in post
    result = await self._request_wrapper(
             ^^^^^^^^^^^^^^^^^^^^^^^^^^^^
  File "/home/shurik/tg_bot/venv/lib/python3.12/site-packages/telegram/request/_baserequest.py", line 375, in _request_wrapper
    raise exception
telegram.error.Conflict: Conflict: terminated by other getUpdates request; make sure that only one bot instance is running
No error handlers are registered, logging exception.
Traceback (most recent call last):
  File "/home/shurik/tg_bot/venv/lib/python3.12/site-packages/telegram/ext/_utils/networkloop.py", line 134, in network_retry_loop
    await do_action()
  File "/home/shurik/tg_bot/venv/lib/python3.12/site-packages/telegram/ext/_utils/networkloop.py", line 127, in do_action
    action_cb_task.result()
  File "/home/shurik/tg_bot/venv/lib/python3.12/site-packages/telegram/ext/_updater.py", line 340, in polling_action_cb
    updates = await self.bot.get_updates(
              ^^^^^^^^^^^^^^^^^^^^^^^^^^^
  File "/home/shurik/tg_bot/venv/lib/python3.12/site-packages/telegram/ext/_extbot.py", line 676, in get_updates
    updates = await super().get_updates(
              ^^^^^^^^^^^^^^^^^^^^^^^^^^
  File "/home/shurik/tg_bot/venv/lib/python3.12/site-packages/telegram/_bot.py", line 4780, in get_updates
    await self._post(
  File "/home/shurik/tg_bot/venv/lib/python3.12/site-packages/telegram/_bot.py", line 703, in _post
    return await self._do_post(
           ^^^^^^^^^^^^^^^^^^^^
  File "/home/shurik/tg_bot/venv/lib/python3.12/site-packages/telegram/ext/_extbot.py", line 372, in _do_post
    return await super()._do_post(
           ^^^^^^^^^^^^^^^^^^^^^^^
  File "/home/shurik/tg_bot/venv/lib/python3.12/site-packages/telegram/_bot.py", line 732, in _do_post
    result = await request.post(
             ^^^^^^^^^^^^^^^^^^^
  File "/home/shurik/tg_bot/venv/lib/python3.12/site-packages/telegram/request/_baserequest.py", line 198, in post
    result = await self._request_wrapper(
             ^^^^^^^^^^^^^^^^^^^^^^^^^^^^
  File "/home/shurik/tg_bot/venv/lib/python3.12/site-packages/telegram/request/_baserequest.py", line 375, in _request_wrapper
    raise exception
telegram.error.Conflict: Conflict: terminated by other getUpdates request; make sure that only one bot instance is running
No error handlers are registered, logging exception.
Traceback (most recent call last):
  File "/home/shurik/tg_bot/venv/lib/python3.12/site-packages/telegram/ext/_utils/networkloop.py", line 134, in network_retry_loop
    await do_action()
  File "/home/shurik/tg_bot/venv/lib/python3.12/site-packages/telegram/ext/_utils/networkloop.py", line 127, in do_action
    action_cb_task.result()
  File "/home/shurik/tg_bot/venv/lib/python3.12/site-packages/telegram/ext/_updater.py", line 340, in polling_action_cb
    updates = await self.bot.get_updates(
              ^^^^^^^^^^^^^^^^^^^^^^^^^^^
  File "/home/shurik/tg_bot/venv/lib/python3.12/site-packages/telegram/ext/_extbot.py", line 676, in get_updates
    updates = await super().get_updates(
              ^^^^^^^^^^^^^^^^^^^^^^^^^^
  File "/home/shurik/tg_bot/venv/lib/python3.12/site-packages/telegram/_bot.py", line 4780, in get_updates
    await self._post(
  File "/home/shurik/tg_bot/venv/lib/python3.12/site-packages/telegram/_bot.py", line 703, in _post
    return await self._do_post(
           ^^^^^^^^^^^^^^^^^^^^
  File "/home/shurik/tg_bot/venv/lib/python3.12/site-packages/telegram/ext/_extbot.py", line 372, in _do_post
    return await super()._do_post(
           ^^^^^^^^^^^^^^^^^^^^^^^
  File "/home/shurik/tg_bot/venv/lib/python3.12/site-packages/telegram/_bot.py", line 732, in _do_post
    result = await request.post(
             ^^^^^^^^^^^^^^^^^^^
  File "/home/shurik/tg_bot/venv/lib/python3.12/site-packages/telegram/request/_baserequest.py", line 198, in post
    result = await self._request_wrapper(
             ^^^^^^^^^^^^^^^^^^^^^^^^^^^^
  File "/home/shurik/tg_bot/venv/lib/python3.12/site-packages/telegram/request/_baserequest.py", line 375, in _request_wrapper
    raise exception
telegram.error.Conflict: Conflict: terminated by other getUpdates request; make sure that only one bot instance is running
No error handlers are registered, logging exception.
Traceback (most recent call last):
  File "/home/shurik/tg_bot/venv/lib/python3.12/site-packages/telegram/ext/_utils/networkloop.py", line 134, in network_retry_loop
    await do_action()
  File "/home/shurik/tg_bot/venv/lib/python3.12/site-packages/telegram/ext/_utils/networkloop.py", line 127, in do_action
    action_cb_task.result()
  File "/home/shurik/tg_bot/venv/lib/python3.12/site-packages/telegram/ext/_updater.py", line 340, in polling_action_cb
    updates = await self.bot.get_updates(
              ^^^^^^^^^^^^^^^^^^^^^^^^^^^
  File "/home/shurik/tg_bot/venv/lib/python3.12/site-packages/telegram/ext/_extbot.py", line 676, in get_updates
    updates = await super().get_updates(
              ^^^^^^^^^^^^^^^^^^^^^^^^^^
  File "/home/shurik/tg_bot/venv/lib/python3.12/site-packages/telegram/_bot.py", line 4780, in get_updates
    await self._post(
  File "/home/shurik/tg_bot/venv/lib/python3.12/site-packages/telegram/_bot.py", line 703, in _post
    return await self._do_post(
           ^^^^^^^^^^^^^^^^^^^^
  File "/home/shurik/tg_bot/venv/lib/python3.12/site-packages/telegram/ext/_extbot.py", line 372, in _do_post
    return await super()._do_post(
           ^^^^^^^^^^^^^^^^^^^^^^^
  File "/home/shurik/tg_bot/venv/lib/python3.12/site-packages/telegram/_bot.py", line 732, in _do_post
    result = await request.post(
             ^^^^^^^^^^^^^^^^^^^
  File "/home/shurik/tg_bot/venv/lib/python3.12/site-packages/telegram/request/_baserequest.py", line 198, in post
    result = await self._request_wrapper(
             ^^^^^^^^^^^^^^^^^^^^^^^^^^^^
  File "/home/shurik/tg_bot/venv/lib/python3.12/site-packages/telegram/request/_baserequest.py", line 375, in _request_wrapper
    raise exception
telegram.error.Conflict: Conflict: terminated by other getUpdates request; make sure that only one bot instance is running
No error handlers are registered, logging exception.
Traceback (most recent call last):
  File "/home/shurik/tg_bot/venv/lib/python3.12/site-packages/telegram/ext/_utils/networkloop.py", line 134, in network_retry_loop
    await do_action()
  File "/home/shurik/tg_bot/venv/lib/python3.12/site-packages/telegram/ext/_utils/networkloop.py", line 127, in do_action
    action_cb_task.result()
  File "/home/shurik/tg_bot/venv/lib/python3.12/site-packages/telegram/ext/_updater.py", line 340, in polling_action_cb
    updates = await self.bot.get_updates(
              ^^^^^^^^^^^^^^^^^^^^^^^^^^^
  File "/home/shurik/tg_bot/venv/lib/python3.12/site-packages/telegram/ext/_extbot.py", line 676, in get_updates
    updates = await super().get_updates(
              ^^^^^^^^^^^^^^^^^^^^^^^^^^
  File "/home/shurik/tg_bot/venv/lib/python3.12/site-packages/telegram/_bot.py", line 4780, in get_updates
    await self._post(
  File "/home/shurik/tg_bot/venv/lib/python3.12/site-packages/telegram/_bot.py", line 703, in _post
    return await self._do_post(
           ^^^^^^^^^^^^^^^^^^^^
  File "/home/shurik/tg_bot/venv/lib/python3.12/site-packages/telegram/ext/_extbot.py", line 372, in _do_post
    return await super()._do_post(
           ^^^^^^^^^^^^^^^^^^^^^^^
  File "/home/shurik/tg_bot/venv/lib/python3.12/site-packages/telegram/_bot.py", line 732, in _do_post
    result = await request.post(
             ^^^^^^^^^^^^^^^^^^^
  File "/home/shurik/tg_bot/venv/lib/python3.12/site-packages/telegram/request/_baserequest.py", line 198, in post
    result = await self._request_wrapper(
             ^^^^^^^^^^^^^^^^^^^^^^^^^^^^
  File "/home/shurik/tg_bot/venv/lib/python3.12/site-packages/telegram/request/_baserequest.py", line 375, in _request_wrapper
    raise exception
telegram.error.Conflict: Conflict: terminated by other getUpdates request; make sure that only one bot instance is running
No error handlers are registered, logging exception.
Traceback (most recent call last):
  File "/home/shurik/tg_bot/venv/lib/python3.12/site-packages/telegram/ext/_utils/networkloop.py", line 134, in network_retry_loop
    await do_action()
  File "/home/shurik/tg_bot/venv/lib/python3.12/site-packages/telegram/ext/_utils/networkloop.py", line 127, in do_action
    action_cb_task.result()
  File "/home/shurik/tg_bot/venv/lib/python3.12/site-packages/telegram/ext/_updater.py", line 340, in polling_action_cb
    updates = await self.bot.get_updates(
              ^^^^^^^^^^^^^^^^^^^^^^^^^^^
  File "/home/shurik/tg_bot/venv/lib/python3.12/site-packages/telegram/ext/_extbot.py", line 676, in get_updates
    updates = await super().get_updates(
              ^^^^^^^^^^^^^^^^^^^^^^^^^^
  File "/home/shurik/tg_bot/venv/lib/python3.12/site-packages/telegram/_bot.py", line 4780, in get_updates
    await self._post(
  File "/home/shurik/tg_bot/venv/lib/python3.12/site-packages/telegram/_bot.py", line 703, in _post
    return await self._do_post(
           ^^^^^^^^^^^^^^^^^^^^
  File "/home/shurik/tg_bot/venv/lib/python3.12/site-packages/telegram/ext/_extbot.py", line 372, in _do_post
    return await super()._do_post(
           ^^^^^^^^^^^^^^^^^^^^^^^
  File "/home/shurik/tg_bot/venv/lib/python3.12/site-packages/telegram/_bot.py", line 732, in _do_post
    result = await request.post(
             ^^^^^^^^^^^^^^^^^^^
  File "/home/shurik/tg_bot/venv/lib/python3.12/site-packages/telegram/request/_baserequest.py", line 198, in post
    result = await self._request_wrapper(
             ^^^^^^^^^^^^^^^^^^^^^^^^^^^^
  File "/home/shurik/tg_bot/venv/lib/python3.12/site-packages/telegram/request/_baserequest.py", line 375, in _request_wrapper
    raise exception
telegram.error.Conflict: Conflict: terminated by other getUpdates request; make sure that only one bot instance is running
No error handlers are registered, logging exception.
Traceback (most recent call last):
  File "/home/shurik/tg_bot/venv/lib/python3.12/site-packages/telegram/ext/_utils/networkloop.py", line 134, in network_retry_loop
    await do_action()
  File "/home/shurik/tg_bot/venv/lib/python3.12/site-packages/telegram/ext/_utils/networkloop.py", line 127, in do_action
    action_cb_task.result()
  File "/home/shurik/tg_bot/venv/lib/python3.12/site-packages/telegram/ext/_updater.py", line 340, in polling_action_cb
    updates = await self.bot.get_updates(
              ^^^^^^^^^^^^^^^^^^^^^^^^^^^
  File "/home/shurik/tg_bot/venv/lib/python3.12/site-packages/telegram/ext/_extbot.py", line 676, in get_updates
    updates = await super().get_updates(
              ^^^^^^^^^^^^^^^^^^^^^^^^^^
  File "/home/shurik/tg_bot/venv/lib/python3.12/site-packages/telegram/_bot.py", line 4780, in get_updates
    await self._post(
  File "/home/shurik/tg_bot/venv/lib/python3.12/site-packages/telegram/_bot.py", line 703, in _post
    return await self._do_post(
           ^^^^^^^^^^^^^^^^^^^^
  File "/home/shurik/tg_bot/venv/lib/python3.12/site-packages/telegram/ext/_extbot.py", line 372, in _do_post
    return await super()._do_post(
           ^^^^^^^^^^^^^^^^^^^^^^^
  File "/home/shurik/tg_bot/venv/lib/python3.12/site-packages/telegram/_bot.py", line 732, in _do_post
    result = await request.post(
             ^^^^^^^^^^^^^^^^^^^
  File "/home/shurik/tg_bot/venv/lib/python3.12/site-packages/telegram/request/_baserequest.py", line 198, in post
    result = await self._request_wrapper(
             ^^^^^^^^^^^^^^^^^^^^^^^^^^^^
  File "/home/shurik/tg_bot/venv/lib/python3.12/site-packages/telegram/request/_baserequest.py", line 375, in _request_wrapper
    raise exception
telegram.error.Conflict: Conflict: terminated by other getUpdates request; make sure that only one bot instance is running
No error handlers are registered, logging exception.
Traceback (most recent call last):
  File "/home/shurik/tg_bot/venv/lib/python3.12/site-packages/telegram/ext/_utils/networkloop.py", line 134, in network_retry_loop
    await do_action()
  File "/home/shurik/tg_bot/venv/lib/python3.12/site-packages/telegram/ext/_utils/networkloop.py", line 127, in do_action
    action_cb_task.result()
  File "/home/shurik/tg_bot/venv/lib/python3.12/site-packages/telegram/ext/_updater.py", line 340, in polling_action_cb
    updates = await self.bot.get_updates(
              ^^^^^^^^^^^^^^^^^^^^^^^^^^^
  File "/home/shurik/tg_bot/venv/lib/python3.12/site-packages/telegram/ext/_extbot.py", line 676, in get_updates
    updates = await super().get_updates(
              ^^^^^^^^^^^^^^^^^^^^^^^^^^
  File "/home/shurik/tg_bot/venv/lib/python3.12/site-packages/telegram/_bot.py", line 4780, in get_updates
    await self._post(
  File "/home/shurik/tg_bot/venv/lib/python3.12/site-packages/telegram/_bot.py", line 703, in _post
    return await self._do_post(
           ^^^^^^^^^^^^^^^^^^^^
  File "/home/shurik/tg_bot/venv/lib/python3.12/site-packages/telegram/ext/_extbot.py", line 372, in _do_post
    return await super()._do_post(
           ^^^^^^^^^^^^^^^^^^^^^^^
  File "/home/shurik/tg_bot/venv/lib/python3.12/site-packages/telegram/_bot.py", line 732, in _do_post
    result = await request.post(
             ^^^^^^^^^^^^^^^^^^^
  File "/home/shurik/tg_bot/venv/lib/python3.12/site-packages/telegram/request/_baserequest.py", line 198, in post
    result = await self._request_wrapper(
             ^^^^^^^^^^^^^^^^^^^^^^^^^^^^
  File "/home/shurik/tg_bot/venv/lib/python3.12/site-packages/telegram/request/_baserequest.py", line 375, in _request_wrapper
    raise exception
telegram.error.Conflict: Conflict: terminated by other getUpdates request; make sure that only one bot instance is running
No error handlers are registered, logging exception.
Traceback (most recent call last):
  File "/home/shurik/tg_bot/venv/lib/python3.12/site-packages/telegram/ext/_utils/networkloop.py", line 134, in network_retry_loop
    await do_action()
  File "/home/shurik/tg_bot/venv/lib/python3.12/site-packages/telegram/ext/_utils/networkloop.py", line 127, in do_action
    action_cb_task.result()
  File "/home/shurik/tg_bot/venv/lib/python3.12/site-packages/telegram/ext/_updater.py", line 340, in polling_action_cb
    updates = await self.bot.get_updates(
              ^^^^^^^^^^^^^^^^^^^^^^^^^^^
  File "/home/shurik/tg_bot/venv/lib/python3.12/site-packages/telegram/ext/_extbot.py", line 676, in get_updates
    updates = await super().get_updates(
              ^^^^^^^^^^^^^^^^^^^^^^^^^^
  File "/home/shurik/tg_bot/venv/lib/python3.12/site-packages/telegram/_bot.py", line 4780, in get_updates
    await self._post(
  File "/home/shurik/tg_bot/venv/lib/python3.12/site-packages/telegram/_bot.py", line 703, in _post
    return await self._do_post(
           ^^^^^^^^^^^^^^^^^^^^
  File "/home/shurik/tg_bot/venv/lib/python3.12/site-packages/telegram/ext/_extbot.py", line 372, in _do_post
    return await super()._do_post(
           ^^^^^^^^^^^^^^^^^^^^^^^
  File "/home/shurik/tg_bot/venv/lib/python3.12/site-packages/telegram/_bot.py", line 732, in _do_post
    result = await request.post(
             ^^^^^^^^^^^^^^^^^^^
  File "/home/shurik/tg_bot/venv/lib/python3.12/site-packages/telegram/request/_baserequest.py", line 198, in post
    result = await self._request_wrapper(
             ^^^^^^^^^^^^^^^^^^^^^^^^^^^^
  File "/home/shurik/tg_bot/venv/lib/python3.12/site-packages/telegram/request/_baserequest.py", line 375, in _request_wrapper
    raise exception
telegram.error.Conflict: Conflict: terminated by other getUpdates request; make sure that only one bot instance is running
No error handlers are registered, logging exception.
Traceback (most recent call last):
  File "/home/shurik/tg_bot/venv/lib/python3.12/site-packages/telegram/ext/_utils/networkloop.py", line 134, in network_retry_loop
    await do_action()
  File "/home/shurik/tg_bot/venv/lib/python3.12/site-packages/telegram/ext/_utils/networkloop.py", line 127, in do_action
    action_cb_task.result()
  File "/home/shurik/tg_bot/venv/lib/python3.12/site-packages/telegram/ext/_updater.py", line 340, in polling_action_cb
    updates = await self.bot.get_updates(
              ^^^^^^^^^^^^^^^^^^^^^^^^^^^
  File "/home/shurik/tg_bot/venv/lib/python3.12/site-packages/telegram/ext/_extbot.py", line 676, in get_updates
    updates = await super().get_updates(
              ^^^^^^^^^^^^^^^^^^^^^^^^^^
  File "/home/shurik/tg_bot/venv/lib/python3.12/site-packages/telegram/_bot.py", line 4780, in get_updates
    await self._post(
  File "/home/shurik/tg_bot/venv/lib/python3.12/site-packages/telegram/_bot.py", line 703, in _post
    return await self._do_post(
           ^^^^^^^^^^^^^^^^^^^^
  File "/home/shurik/tg_bot/venv/lib/python3.12/site-packages/telegram/ext/_extbot.py", line 372, in _do_post
    return await super()._do_post(
           ^^^^^^^^^^^^^^^^^^^^^^^
  File "/home/shurik/tg_bot/venv/lib/python3.12/site-packages/telegram/_bot.py", line 732, in _do_post
    result = await request.post(
             ^^^^^^^^^^^^^^^^^^^
  File "/home/shurik/tg_bot/venv/lib/python3.12/site-packages/telegram/request/_baserequest.py", line 198, in post
    result = await self._request_wrapper(
             ^^^^^^^^^^^^^^^^^^^^^^^^^^^^
  File "/home/shurik/tg_bot/venv/lib/python3.12/site-packages/telegram/request/_baserequest.py", line 375, in _request_wrapper
    raise exception
telegram.error.Conflict: Conflict: terminated by other getUpdates request; make sure that only one bot instance is running
